<html>
  <head>
    <meta charset="utf-8" />
<meta name="description" content="" />
<meta name="viewport" content="width=device-width, initial-scale=1" />
<title>Python - 错误、调试和测试 | Lixin-SCUT</title>
<link rel="shortcut icon" href="https://lixin-scut.github.io//favicon.ico?v=1589766718370">
<link rel="stylesheet" href="https://use.fontawesome.com/releases/v5.7.2/css/all.css" integrity="sha384-fnmOCqbTlWIlj8LyTjo7mOUStjsKC4pOpQbqyi7RrhN7udi9RwhKkMHpvLbHG9Sr" crossorigin="anonymous">
<link rel="stylesheet" href="https://cdnjs.cloudflare.com/ajax/libs/KaTeX/0.10.0/katex.min.css">
<link rel="stylesheet" href="https://lixin-scut.github.io//styles/main.css">

<script src="https://cdn.bootcss.com/highlight.js/9.12.0/highlight.min.js"></script>
<script src="https://cdn.bootcss.com/moment.js/2.23.0/moment.min.js"></script>



  </head>
  <body>
    <div class="main">
      <div class="main-content">
        <div class="site-header">
  <a href="https://lixin-scut.github.io/">
  <img class="avatar" src="https://lixin-scut.github.io//images/avatar.png?v=1589766718370" alt="">
  </a>
  <h1 class="site-title">
    Lixin-SCUT
  </h1>
  <p class="site-description">
    千里之行，始于足下。不积跬步，无以至千里。
  </p>
  <div class="menu-container">
    
      
        <a href="/" class="menu">
          首页
        </a>
      
    
      
        <a href="/archives" class="menu">
          时间轴
        </a>
      
    
      
        <a href="/tags" class="menu">
          分类/标签
        </a>
      
    
      
        <a href="/post/about" class="menu">
          关于
        </a>
      
    
  </div>
  <div class="social-container">
    
      
    
      
    
      
    
      
    
      
    
  </div>
</div>


        <div class="post-detail">
          <article class="post">
            <h2 class="post-title">
              Python - 错误、调试和测试
            </h2>
            <div class="post-info">
              <time class="post-time">
                · 2020-05-12 ·
              </time>
              
                <a href="https://lixin-scut.github.io//tag/qC53A8dj2" class="post-tag">
                  # Python
                </a>
              
                <a href="https://lixin-scut.github.io//tag/FaScKSk5i" class="post-tag">
                  # 读书笔记
                </a>
              
            </div>
            
            <div class="post-content">
              <p>在程序运行过程中，总会遇到各种各样的错误。</p>
<p>有的错误是程序编写有问题造成的，比如本来应该输出整数结果输出了字符串，这种错误我们通常称之为bug，bug是必须修复的。</p>
<p>有的错误是用户输入造成的，比如让用户输入email地址，结果得到一个空字符串，这种错误可以通过检查用户输入来做相应的处理。</p>
<p>还有一类错误是完全无法在程序运行过程中预测的，比如写入文件的时候，磁盘满了，写不进去了，或者从网络抓取数据，网络突然断掉了。这类错误也称为异常，在程序中通常是必须处理的，否则，程序会因为各种问题终止并退出。</p>
<p>Python内置了一套异常处理机制，来帮助我们进行错误处理。</p>
<p>此外，我们也需要跟踪程序的执行，查看变量的值是否正确，这个过程称为调试。Python的pdb可以让我们以单步方式执行代码。</p>
<p>最后，编写测试也很重要。有了良好的测试，就可以在程序修改后反复运行，确保程序输出符合我们编写的测试。</p>
<h2 id="错误处理">错误处理</h2>
<p>在程序运行的过程中，如果发生了错误，可以事先约定返回一个错误代码，这样，就可以知道是否有错，以及出错的原因。在操作系统提供的调用中，返回错误码非常常见。比如打开文件的函数open()，成功时返回文件描述符（就是一个整数），出错时返回-1。</p>
<p>用错误码来表示是否出错十分不便，因为函数本身应该返回的正常结果和错误码混在一起，造成调用者必须用大量的代码来判断是否出错：</p>
<pre><code>def foo():
    r = some_function()
    if r==(-1):
        return (-1)
    # do something
    return r

def bar():
    r = foo()
    if r==(-1):
        print('Error')
    else:
        pass
</code></pre>
<p>一旦出错，还要一级一级上报，直到某个函数可以处理该错误（比如，给用户输出一个错误信息）。</p>
<h3 id="tryexceptfinally">try...except...finally...</h3>
<p>所以高级语言通常都内置了一套try...except...finally...的错误处理机制，Python也不例外。</p>
<h3 id="try">try</h3>
<p>让我们用一个例子来看看try的机制：</p>
<pre><code>try:
    print('try...')
    r = 10 / 0
    print('result:', r)
except ZeroDivisionError as e:
    print('except:', e)
finally:
    print('finally...')
print('END')
</code></pre>
<p>当我们认为某些代码可能会出错时，就可以用try来运行这段代码，如果执行出错，则后续代码不会继续执行，而是直接跳转至错误处理代码，即except语句块，<strong>执行完except后，如果有finally语句块，则执行finally语句块</strong>，至此，执行完毕。</p>
<p>上面的代码在计算10 / 0时会产生一个除法运算错误：</p>
<pre><code>try...
except: division by zero
finally...
END
</code></pre>
<p>从输出可以看到，当错误发生时，后续语句print('result:', r)不会被执行，except由于捕获到ZeroDivisionError，因此被执行。最后，finally语句被执行。然后，程序继续按照流程往下走。</p>
<p>如果把除数0改成2，则执行结果如下：</p>
<pre><code>try...
result: 5
finally...
END
</code></pre>
<p>由于没有错误发生，所以except语句块不会被执行，但是finally如果有，则一定会被执行（可以没有finally语句）。</p>
<p>你还可以猜测，错误应该有很多种类，如果发生了不同类型的错误，应该由不同的except语句块处理。没错，可以<strong>有多个except来捕获不同类型的错误</strong>：</p>
<pre><code>try:
    print('try...')
    r = 10 / int('a')
    print('result:', r)
except ValueError as e:
    print('ValueError:', e)
except ZeroDivisionError as e:
    print('ZeroDivisionError:', e)
finally:
    print('finally...')
print('END')
</code></pre>
<p>int()函数可能会抛出ValueError，所以我们用一个except捕获ValueError，用另一个except捕获ZeroDivisionError。</p>
<h3 id="else">else</h3>
<p>此外，如果没有错误发生，可以<strong>在except语句块后面加一个else，当没有错误发生时，会自动执行else语句</strong>：</p>
<pre><code>try:
    print('try...')
    r = 10 / int('2')
    print('result:', r)
except ValueError as e:
    print('ValueError:', e)
except ZeroDivisionError as e:
    print('ZeroDivisionError:', e)
else:
    print('no error!')
finally:
    print('finally...')
print('END')
</code></pre>
<h3 id="错误类">错误类</h3>
<p>Python的<strong>错误其实也是class</strong>，<strong>所有的错误类型都继承自BaseException</strong>，所以在使用except时需要注意的是，它<strong>不但捕获该类型的错误，还把其子类也“一网打尽”</strong>。比如：</p>
<pre><code>try:
    foo()
except ValueError as e:
    print('ValueError')
except UnicodeError as e:
    print('UnicodeError')
</code></pre>
<p>第二个except<strong>永远也捕获不到UnicodeError</strong>，<strong>因为UnicodeError是ValueError的子类，如果有，也被第一个except给捕获了</strong>。</p>
<p><strong>Python所有的错误都是从BaseException类派生</strong>的，常见的错误类型和继承关系看这里：</p>
<p><a href="https://docs.python.org/3/library/exceptions.html#exception-hierarchy">错误类型和继承关系</a></p>
<h3 id="跨越多层调用">跨越多层调用</h3>
<p>使用try...except捕获错误还有一个巨大的好处，就是可以<strong>跨越多层调用</strong>，比如函数main()调用bar()，bar()调用foo()，结果foo()出错了，这时，<strong>只要main()捕获到了，就可以处理</strong>：</p>
<pre><code>def foo(s):
    return 10 / int(s)

def bar(s):
    return foo(s) * 2

def main():
    try:
        bar('0')
    except Exception as e:
        print('Error:', e)
    finally:
        print('finally...')
</code></pre>
<p>也就是说，<strong>不需要在每个可能出错的地方去捕获错误，只要在合适的层次去捕获错误就可以了</strong>。这样一来，就大大减少了写try...except...finally的麻烦。</p>
<h3 id="调用栈">调用栈</h3>
<p><strong>如果错误没有被捕获，它就会一直往上抛，最后被Python解释器捕获，打印一个错误信息，然后程序退出</strong>。</p>
<p>来看看err.py：</p>
<pre><code># err.py:
def foo(s):
    return 10 / int(s)

def bar(s):
    return foo(s) * 2

def main():
    bar('0')

main()
</code></pre>
<p>执行，结果如下：</p>
<pre><code>$ python3 err.py
Traceback (most recent call last):
  File &quot;err.py&quot;, line 11, in &lt;module&gt;
    main()
  File &quot;err.py&quot;, line 9, in main
    bar('0')
  File &quot;err.py&quot;, line 6, in bar
    return foo(s) * 2
  File &quot;err.py&quot;, line 3, in foo
    return 10 / int(s)
ZeroDivisionError: division by zero
</code></pre>
<p>解读错误信息是定位错误的关键。我们从上往下可以看到整个错误的调用函数链：</p>
<p>错误信息第1行：</p>
<pre><code>Traceback (most recent call last):
</code></pre>
<p>告诉我们这是错误的跟踪信息。</p>
<p>第2~3行：</p>
<pre><code>  File &quot;err.py&quot;, line 11, in &lt;module&gt;
    main()
</code></pre>
<p>调用main()出错了，在代码文件err.py的第11行代码，但原因是第9行：</p>
<pre><code>  File &quot;err.py&quot;, line 9, in main
    bar('0')
</code></pre>
<p>调用bar('0')出错了，在代码文件err.py的第9行代码，但原因是第6行：</p>
<pre><code>  File &quot;err.py&quot;, line 6, in bar
    return foo(s) * 2
</code></pre>
<p>原因是return foo(s) * 2这个语句出错了，但这还不是最终原因，继续往下看：</p>
<pre><code>File &quot;err.py&quot;, line 3, in foo
   return 10 / int(s)
</code></pre>
<p>原因是return 10 / int(s)这个语句出错了，这是错误产生的源头，因为下面打印了：</p>
<pre><code>ZeroDivisionError: integer division or modulo by zero
</code></pre>
<p>根据错误类型ZeroDivisionError，我们判断，int(s)本身并没有出错，但是int(s)返回0，在计算10 / 0时出错，至此，找到错误源头。</p>
<p>出错的时候，一定要分析错误的调用栈信息，才能定位错误的位置。</p>
<h3 id="记录错误logging">记录错误logging</h3>
<p>如果不捕获错误，自然可以让Python解释器来打印出错误堆栈，但程序也被结束了。既然我们能捕获错误，就可以<strong>把错误堆栈打印出来，然后分析错误原因，同时，让程序继续执行下去</strong>。</p>
<p>Python内置的logging模块可以非常容易地记录错误信息：</p>
<pre><code>
# err_logging.py

import logging

def foo(s):
    return 10 / int(s)

def bar(s):
    return foo(s) * 2

def main():
    try:
        bar('0')
    except Exception as e:
        logging.exception(e)

main()
print('END')

</code></pre>
<p>同样是出错，但<strong>程序打印完错误信息后会继续执行，并正常退出</strong>：</p>
<pre><code>$ python3 err_logging.py
ERROR:root:division by zero
Traceback (most recent call last):
  File &quot;err_logging.py&quot;, line 13, in main
    bar('0')
  File &quot;err_logging.py&quot;, line 9, in bar
    return foo(s) * 2
  File &quot;err_logging.py&quot;, line 6, in foo
    return 10 / int(s)
ZeroDivisionError: division by zero
END
</code></pre>
<p><strong>通过配置，logging还可以把错误记录到日志文件里，方便事后排查。</strong></p>
<h3 id="抛出错误">抛出错误</h3>
<p>因为错误是class，捕获一个错误就是捕获到该class的一个实例。因此，<strong>错误并不是凭空产生的，而是有意创建并抛出的</strong>。Python的内置函数会抛出很多类型的错误，我们自己编写的函数也可以抛出错误。</p>
<p>如果要抛出错误，首先根据需要，<strong>可以定义一个错误的class，选择好继承关系</strong>，然后，用<strong>raise语句抛出一个错误的实例</strong>：</p>
<pre><code>
# err_raise.py
class FooError(ValueError):
    pass

def foo(s):
    n = int(s)
    if n==0:
        raise FooError('invalid value: %s' % s)
    return 10 / n

foo('0')
</code></pre>
<p>执行，可以最后跟踪到我们自己定义的错误：</p>
<pre><code>$ python3 err_raise.py 
Traceback (most recent call last):
  File &quot;err_throw.py&quot;, line 11, in &lt;module&gt;
    foo('0')
  File &quot;err_throw.py&quot;, line 8, in foo
    raise FooError('invalid value: %s' % s)
__main__.FooError: invalid value: 0

</code></pre>
<p><strong>只有在必要的时候才定义我们自己的错误类型。如果可以选择Python已有的内置的错误类型（比如ValueError，TypeError），尽量使用Python内置的错误类型。</strong></p>
<p>最后，我们来看另一种错误处理的方式：</p>
<pre><code>
# err_reraise.py

def foo(s):
    n = int(s)
    if n==0:
        raise ValueError('invalid value: %s' % s)
    return 10 / n

def bar():
    try:
        foo('0')
    except ValueError as e:
        print('ValueError!')
        raise

bar()

</code></pre>
<p>在bar()函数中，我们明明已经捕获了错误，但是，<strong>打印一个ValueError!后，又把错误通过raise语句抛出去了</strong></p>
<p>其实这种错误处理方式相当常见。捕获错误目的只是记录一下，便于后续追踪。但是，<strong>由于当前函数不知道应该怎么处理该错误</strong>，所以，<strong>最恰当的方式是继续往上抛，让顶层调用者去处理</strong>。好比一个员工处理不了一个问题时，就把问题抛给他的老板，如果他的老板也处理不了，就一直往上抛，最终会抛给CEO去处理。</p>
<p><strong>raise语句如果不带参数，就会把当前错误原样抛出</strong>。</p>
<p>此外，<strong>在except中raise一个Error，还可以把一种类型的错误转化成另一种类型</strong>：</p>
<pre><code>try:
    10 / 0
except ZeroDivisionError:
    raise ValueError('input error!')
</code></pre>
<p>只要是<strong>合理的转换逻辑</strong>就可以，但是，<strong>决不应该把一个IOError转换成毫不相干的ValueError</strong>。</p>
<h3 id="小结">小结</h3>
<p>Python内置的try...except...finally用来处理错误十分方便。出错时，会分析错误信息并定位错误发生的代码位置才是最关键的。</p>
<p>程序也可以主动抛出错误，让调用者来处理相应的错误。但是，<strong>应该在文档中写清楚可能会抛出哪些错误，以及错误产生的原因</strong>。</p>
<p><strong>个人代码练习</strong><br>
运行下面的代码，根据异常信息进行分析，定位出错误源头，并修复：</p>
<pre><code>
# -*- coding: utf-8 -*-
from functools import reduce

def str2num(s):
    # return int(s)
    try:
        return int(s)
    except ValueError:
        return float(s)

def calc(exp):
    ss = exp.split('+')
    ns = map(str2num, ss)
    return reduce(lambda acc, x: acc + x, ns)

def main():
    r = calc('100 + 200 + 345')
    print('100 + 200 + 345 =', r)
    r = calc('99 + 88 + 7.6')
    print('99 + 88 + 7.6 =', r)

main()

</code></pre>
<h2 id="调试">调试</h2>
<p>程序能一次写完并正常运行的概率很小，总会有各种各样的bug需要修正。有的bug很简单，看看错误信息就知道，有的bug很复杂，我们需要知道出错时，哪些变量的值是正确的，哪些变量的值是错误的，因此，需要<strong>一整套调试程序的手段来修复bug</strong>。</p>
<h3 id="打印变量">打印变量</h3>
<p>第一种方法简单直接粗暴有效，就是用print()把可能有问题的变量打印出来看看：</p>
<pre><code>def foo(s):
    n = int(s)
    print('&gt;&gt;&gt; n = %d' % n)
    return 10 / n

def main():
    foo('0')

main()
</code></pre>
<p>执行后在输出中查找打印的变量值：</p>
<pre><code>$ python err.py
&gt;&gt;&gt; n = 0
Traceback (most recent call last):
  ...
ZeroDivisionError: integer division or modulo by zero
</code></pre>
<p><strong>用print()最大的坏处是将来还得删掉它</strong>，想想程序里到处都是print()，运行结果也会包含很多垃圾信息。所以，我们又有第二种方法。</p>
<h3 id="断言">断言</h3>
<p><strong>凡是用print()来辅助查看的地方，都可以用断言（assert）来替代</strong>：</p>
<pre><code>def foo(s):
    n = int(s)
    assert n != 0, 'n is zero!'
    return 10 / n

def main():
    foo('0')
</code></pre>
<p><strong>assert的意思是，表达式n != 0应该是True，否则，根据程序运行的逻辑，后面的代码肯定会出错</strong>。</p>
<p><strong>如果断言失败，assert语句本身就会抛出AssertionError</strong>：</p>
<pre><code>$ python err.py
Traceback (most recent call last):
  ...
AssertionError: n is zero!
</code></pre>
<p>程序中如果到处充斥着assert，和print()相比也好不到哪去。<br>
不过，启<strong>动Python解释器时可以用-O参数来关闭assert</strong>：</p>
<pre><code>$ python -O err.py
Traceback (most recent call last):
  ...
ZeroDivisionError: division by zero
</code></pre>
<p><strong>注意：断言的开关“-O”是英文大写字母O，不是数字0。</strong><br>
<strong>关闭后，你可以把所有的assert语句当成pass来看</strong>。</p>
<h3 id="logging">logging</h3>
<p>把print()替换为logging是第3种方式，和assert比，<strong>logging不会抛出错误，而且可以输出到文件</strong>：</p>
<pre><code>import logging

s = '0'
n = int(s)
logging.info('n = %d' % n)
print(10 / n)
</code></pre>
<p>logging.info()就可以输出一段文本。运行，发现除了ZeroDivisionError，没有任何输出信息。</p>
<p>然后再在import logging之后添加一行配置再试试：</p>
<pre><code>import logging
logging.basicConfig(level=logging.INFO)
</code></pre>
<p>可以看到输出了：</p>
<pre><code>$ python err.py
INFO:root:n = 0
Traceback (most recent call last):
  File &quot;err.py&quot;, line 8, in &lt;module&gt;
    print(10 / n)
ZeroDivisionError: division by zero
</code></pre>
<p><strong>信息级别</strong><br>
这就是logging的好处，它<strong>允许你指定记录信息的级别，有debug，info，warning，error等几个级别</strong>，<strong>当我们指定level=INFO时，logging.debug就不起作用了。同理，指定level=WARNING后，debug和info就不起作用了</strong>。这样一来，你可以放心地输出不同级别的信息，也不用删除，最后统一控制输出哪个级别的信息。</p>
<p>logging的另一个好处是通过简单的配置，<strong>一条语句可以同时输出到不同的地方</strong>，比如console和文件。</p>
<h3 id="pdb">pdb</h3>
<p>第4种方式是启动Python的<strong>调试器pdb</strong>，<strong>让程序以单步方式运行，可以随时查看运行状态</strong>。</p>
<p>准备好程序：</p>
<pre><code># err.py
s = '0'
n = int(s)
print(10 / n)
</code></pre>
<p>然后启动：</p>
<pre><code>$ python -m pdb err.py
&gt; /Users/michael/Github/learn-python3/samples/debug/err.py(2)&lt;module&gt;()
-&gt; s = '0'
</code></pre>
<p>以<strong>参数-m pdb</strong>启动后，pdb定位到下一步要执行的代码-&gt; s = '0'。</p>
<p><strong>输入命令l来查看代码</strong>：</p>
<pre><code>(Pdb) l
  1     # err.py
  2  -&gt; s = '0'
  3     n = int(s)
  4     print(10 / n)
</code></pre>
<p><strong>输入命令n可以单步执行代码</strong>：</p>
<pre><code>(Pdb) n
&gt; /Users/michael/Github/learn-python3/samples/debug/err.py(3)&lt;module&gt;()
-&gt; n = int(s)
(Pdb) n
&gt; /Users/michael/Github/learn-python3/samples/debug/err.py(4)&lt;module&gt;()
-&gt; print(10 / n)
</code></pre>
<p>任何时候都可以<strong>输入命令p 变量名来查看变量</strong>：</p>
<pre><code>(Pdb) p s
'0'
(Pdb) p n
0
</code></pre>
<p><strong>输入命令q结束调试</strong>，退出程序：</p>
<pre><code>(Pdb) q
</code></pre>
<p>这种通过pdb在命令行调试的方法理论上是万能的，但实在是太麻烦了，如果有一千行代码，要运行到第999行得敲许多重复命令命令啊。还好，我们还有另一种调试方法。</p>
<h3 id="断点-pdbset_trace">断点 pdb.set_trace()</h3>
<p>这个方法也是用pdb，但是不需要单步执行，我们<strong>只需要import pdb</strong>，然后，<strong>在可能出错的地方放一个pdb.set_trace()</strong>，就可以设置一个断点：</p>
<pre><code># err.py
import pdb

s = '0'
n = int(s)
pdb.set_trace() # 运行到这里会自动暂停
print(10 / n)
</code></pre>
<p>运行代码，<strong>程序会自动在pdb.set_trace()暂停并进入pdb调试环境</strong>，可以用命令p查看变量，或者<strong>用命令c继续运行</strong>：</p>
<pre><code>$ python err.py 
&gt; /Users/michael/Github/learn-python3/samples/debug/err.py(7)&lt;module&gt;()
-&gt; print(10 / n)
(Pdb) p n
0
(Pdb) c
Traceback (most recent call last):
  File &quot;err.py&quot;, line 7, in &lt;module&gt;
    print(10 / n)
ZeroDivisionError: division by zero
</code></pre>
<p>这个方式比直接启动pdb单步调试效率要高很多，但也高不到哪去。</p>
<h3 id="ide">IDE</h3>
<p>如果要比较快捷地设置断点、单步执行，就需要一个支持调试功能的IDE。目前比较好的Python IDE有：</p>
<p><a href="https://code.visualstudio.com/">Visual Studio Code</a> 注意需要安装Python插件。</p>
<p><a href="http://www.jetbrains.com/pycharm/">PyCharm</a></p>
<p>另外，Eclipse加上pydev插件也可以调试Python程序。</p>
<p>虽然用IDE调试起来比较方便，但是最后你会发现，logging才是终极武器。</p>
<h2 id="单元测试">单元测试</h2>
<p>如果你听说过“测试驱动开发”（TDD：Test-Driven Development），单元测试就不陌生。</p>
<p><strong>单元测试是用来对一个模块、一个函数或者一个类来进行正确性检验的测试工作</strong>。</p>
<p>比如对函数abs()，我们可以编写出以下几个测试用例：</p>
<p>输入正数，比如1、1.2、0.99，期待返回值与输入相同；</p>
<p>输入负数，比如-1、-1.2、-0.99，期待返回值与输入相反；</p>
<p>输入0，期待返回0；</p>
<p>输入非数值类型，比如None、[]、{}，期待抛出TypeError。</p>
<p>把上面的测试用例放到一个测试模块里，就是一个完整的单元测试。</p>
<p>如果单元测试通过，说明我们测试的这个函数能够正常工作。如果单元测试不通过，要么函数有bug，要么测试条件输入不正确，总之，需要修复使单元测试能够通过。</p>
<p>单元测试通过后有什么意义呢？如果我们对abs()函数代码做了修改，只需要再跑一遍单元测试，如果通过，说明我们的修改不会对abs()函数原有的行为造成影响，如果测试不通过，说明我们的修改与原有行为不一致，要么修改代码，要么修改测试。</p>
<p>这种以测试为驱动的开发模式最大的好处就是<strong>确保一个程序模块的行为符合我们设计的测试用例</strong>。在将来修改的时候，可以极大程度地保证该模块行为仍然是正确的。</p>
<p>编写一个Dict类，这个类的行为和dict一致，但是可以通过属性来访问，用起来就像下面这样：</p>
<pre><code>&gt;&gt;&gt; d = Dict(a=1, b=2)
&gt;&gt;&gt; d['a']
1
&gt;&gt;&gt; d.a
1
</code></pre>
<p>mydict.py代码如下：</p>
<pre><code>class Dict(dict):

    def __init__(self, **kw):
        super().__init__(**kw)

    def __getattr__(self, key):
        try:
            return self[key]
        except KeyError:
            raise AttributeError(r&quot;'Dict' object has no attribute '%s'&quot; % key)

    def __setattr__(self, key, value):
        self[key] = value
</code></pre>
<h3 id="unittest模块">unittest模块</h3>
<p>为了编写单元测试，我们需要引入Python自带的unittest模块，编写mydict_test.py如下：</p>
<pre><code>import unittest

from mydict import Dict

class TestDict(unittest.TestCase):

    def test_init(self):
        d = Dict(a=1, b='test')
        self.assertEqual(d.a, 1)
        self.assertEqual(d.b, 'test')
        self.assertTrue(isinstance(d, dict))

    def test_key(self):
        d = Dict()
        d['key'] = 'value'
        self.assertEqual(d.key, 'value')

    def test_attr(self):
        d = Dict()
        d.key = 'value'
        self.assertTrue('key' in d)
        self.assertEqual(d['key'], 'value')

    def test_keyerror(self):
        d = Dict()
        with self.assertRaises(KeyError):
            value = d['empty']

    def test_attrerror(self):
        d = Dict()
        with self.assertRaises(AttributeError):
            value = d.empty
</code></pre>
<p>编写单元测试时，我们<strong>需要编写一个测试类，从unittest.TestCase继承</strong>。</p>
<p><strong>以test开头的方法就是测试方法，不以test开头的方法不被认为是测试方法，测试的时候不会被执行。</strong></p>
<p>对每一类测试都需要编写一个test_xxx()方法。由于<strong>unittest.TestCase提供了很多内置的条件判断</strong>，我们只需要调用这些方法就可以断言输出是否是我们所期望的。<strong>最常用的断言就是assertEqual()</strong>：</p>
<pre><code>self.assertEqual(abs(-1), 1) # 断言函数返回的结果与1相等
</code></pre>
<p>另一种重要的断言就是assertRaises，期待抛出指定类型的Error，比如通过d['empty']访问不存在的key时，断言会抛出KeyError：</p>
<pre><code>with self.assertRaises(KeyError):
    value = d['empty']
</code></pre>
<p>而通过d.empty访问不存在的key时，我们期待抛出AttributeError：</p>
<pre><code>with self.assertRaises(AttributeError):
    value = d.empty
</code></pre>
<h3 id="运行单元测试">运行单元测试</h3>
<p>一旦编写好单元测试，我们就可以运行单元测试。最简单的运行方式是在<code>mydict_test.py</code>的最后加上两行代码：</p>
<pre><code>if __name__ == '__main__':
    unittest.main()
</code></pre>
<p>这样就可以把<code>mydict_test.py</code>当做正常的python脚本运行：</p>
<pre><code>$ python mydict_test.py
</code></pre>
<p>另一种方法是在命令行通过参数<code>-m unittest</code>直接运行单元测试：</p>
<pre><code>$ python -m unittest mydict_test
.....
----------------------------------------------------------------------
Ran 5 tests in 0.000s

OK
</code></pre>
<p>这是推荐的做法，因为这样<strong>可以一次批量运行很多单元测试</strong>，并且，<strong>有很多工具可以自动来运行这些单元测试</strong>。</p>
<h3 id="setup与teardown">setUp与tearDown</h3>
<p>可以在单元测试中编写两个特殊的setUp()和tearDown()方法。这两个方法会分别<strong>在每调用一个测试方法的前后</strong>分别被执行。</p>
<p>设想你的测试需要启动一个数据库，这时，<strong>就可以在setUp()方法中连接数据库，在tearDown()方法中关闭数据库</strong>，这样，不必在每个测试方法中重复相同的代码：</p>
<pre><code>class TestDict(unittest.TestCase):

    def setUp(self):
        print('setUp...')

    def tearDown(self):
        print('tearDown...')
</code></pre>
<p>再次运行测试看看每个测试方法调用前后是否会打印出setUp...和tearDown...。</p>
<p><strong>个人练习代码</strong><br>
对Student类编写单元测试，结果发现测试不通过，请修改Student类，让测试通过：</p>
<pre><code># -*- coding: utf-8 -*-
import unittest

class Student(object):
    def __init__(self, name, score):
        self.name = name
        self.score = score
    def get_grade(self):
        if self.score &lt; 0 or self.score &gt; 100:
            raise ValueError
        if self.score &gt;= 80:
            return 'A'
        if self.score &gt;= 60:
            return 'B'
        return 'C'
				
		class TestStudent(unittest.TestCase):

    def test_80_to_100(self):
        s1 = Student('Bart', 80)
        s2 = Student('Lisa', 100)
        self.assertEqual(s1.get_grade(), 'A')
        self.assertEqual(s2.get_grade(), 'A')

    def test_60_to_80(self):
        s1 = Student('Bart', 60)
        s2 = Student('Lisa', 79)
        self.assertEqual(s1.get_grade(), 'B')
        self.assertEqual(s2.get_grade(), 'B')

    def test_0_to_60(self):
        s1 = Student('Bart', 0)
        s2 = Student('Lisa', 59)
        self.assertEqual(s1.get_grade(), 'C')
        self.assertEqual(s2.get_grade(), 'C')

    def test_invalid(self):
        s1 = Student('Bart', -1)
        s2 = Student('Lisa', 101)
        with self.assertRaises(ValueError):
            s1.get_grade()
        with self.assertRaises(ValueError):
            s2.get_grade()

if __name__ == '__main__':
    unittest.main()
</code></pre>
<h2 id="文档测试">文档测试</h2>
<p>如果你经常阅读Python的官方文档，可以看到很多文档都有示例代码。比如re模块就带了很多示例代码：</p>
<pre><code>&gt;&gt;&gt; import re
&gt;&gt;&gt; m = re.search('(?&lt;=abc)def', 'abcdef')
&gt;&gt;&gt; m.group(0)
'def'
</code></pre>
<p>可以把这些示例代码在Python的交互式环境下输入并执行，结果与文档中的示例代码显示的一致。</p>
<p>这些代码与其他说明可以写在注释中，然后，由一些工具来自动生成文档。既然这些代码本身就可以粘贴出来直接运行，那么，可不可以自动执行写在注释中的这些代码呢？</p>
<p>答案是肯定的。</p>
<p>当我们编写注释时，如果写上这样的注释：</p>
<pre><code>def abs(n):
    '''
    Function to get absolute value of number.
    
    Example:
    
    &gt;&gt;&gt; abs(1)
    1
    &gt;&gt;&gt; abs(-1)
    1
    &gt;&gt;&gt; abs(0)
    0
    '''
    return n if n &gt;= 0 else (-n)
</code></pre>
<p>无疑更明确地告诉函数的调用者该函数的期望输入和输出。</p>
<p><strong>Python内置的“文档测试”（doctest）模块可以直接提取注释中的代码并执行测试</strong>。</p>
<p>doctest严格按照Python交互式命令行的输入和输出来判断测试结果是否正确。只有测试异常的时候，可以用...表示中间一大段烦人的输出。</p>
<p>让我们用doctest来测试上次编写的Dict类：</p>
<pre><code># mydict2.py
class Dict(dict):
    # 注意在class内部
    '''
    Simple dict but also support access as x.y style.

    &gt;&gt;&gt; d1 = Dict()
    &gt;&gt;&gt; d1['x'] = 100
    &gt;&gt;&gt; d1.x
    100
    &gt;&gt;&gt; d1.y = 200
    &gt;&gt;&gt; d1['y']
    200
    &gt;&gt;&gt; d2 = Dict(a=1, b=2, c='3')
    &gt;&gt;&gt; d2.c
    '3'
    &gt;&gt;&gt; d2['empty']
    Traceback (most recent call last):
        ...
    KeyError: 'empty'
    &gt;&gt;&gt; d2.empty
    Traceback (most recent call last):
        ...
    AttributeError: 'Dict' object has no attribute 'empty'
    '''
    def __init__(self, **kw):
        super(Dict, self).__init__(**kw)

    def __getattr__(self, key):
        try:
            return self[key]
        except KeyError:
            raise AttributeError(r&quot;'Dict' object has no attribute '%s'&quot; % key)

    def __setattr__(self, key, value):
        self[key] = value

if __name__=='__main__':
    import doctest
    doctest.testmod()
</code></pre>
<p>运行<code>python mydict2.py</code>：</p>
<pre><code>$ python mydict2.py
</code></pre>
<p>什么输出也没有。<strong>这说明我们编写的doctest运行都是正确的。如果程序有问题，比如把getattr()方法注释掉，再运行就会报错</strong>：</p>
<pre><code>$ python mydict2.py
**********************************************************************
File &quot;/Users/michael/Github/learn-python3/samples/debug/mydict2.py&quot;, line 10, in __main__.Dict
Failed example:
    d1.x
Exception raised:
    Traceback (most recent call last):
      ...
    AttributeError: 'Dict' object has no attribute 'x'
**********************************************************************
File &quot;/Users/michael/Github/learn-python3/samples/debug/mydict2.py&quot;, line 16, in __main__.Dict
Failed example:
    d2.c
Exception raised:
    Traceback (most recent call last):
      ...
    AttributeError: 'Dict' object has no attribute 'c'
**********************************************************************
1 items had failures:
   2 of   9 in __main__.Dict
***Test Failed*** 2 failures.
</code></pre>
<p><strong>注意到最后3行代码。当模块正常导入时，doctest不会被执行。只有在命令行直接运行时，才执行doctest。所以，不必担心doctest会在非测试环境下执行。</strong></p>

            </div>
          </article>
        </div>

        
          <div class="next-post">
            <div class="next">下一篇</div>
            <a href="https://lixin-scut.github.io//post/git-zi-ding-yi-git">
              <h3 class="post-title">
                Git - 自定义Git
              </h3>
            </a>
          </div>
        

        
          
            <link rel="stylesheet" href="https://unpkg.com/gitalk/dist/gitalk.css">
<script src="https://unpkg.com/gitalk/dist/gitalk.min.js"></script>

<div id="gitalk-container"></div>

<script>

  var gitalk = new Gitalk({
    clientID: '253c8689f3b11b51dcf1',
    clientSecret: '64df7c097665e7dd6f416ecfaba36581a91bdb63',
    repo: 'Lixin-SCUT.github.io',
    owner: 'Lixin-SCUT',
    admin: ['Lixin-SCUT'],
    id: (location.pathname).substring(0, 49),      // Ensure uniqueness and length less than 50
    distractionFreeMode: false  // Facebook-like distraction free mode
  })

  gitalk.render('gitalk-container')

</script>

          

          
        

        <div class="site-footer">
  Powered by <a href="https://github.com/getgridea/gridea" target="_blank">Gridea</a> | 
  <a class="rss" href="https://lixin-scut.github.io//atom.xml" target="_blank">RSS</a>
</div>

<script>
  hljs.initHighlightingOnLoad()
</script>

      </div>
    </div>
  </body>
</html>
